{
 "cells": [
  {
   "cell_type": "markdown",
   "id": "4bea0378",
   "metadata": {},
   "source": [
    "https://docs.python.org/3/tutorial/index.html"
   ]
  },
  {
   "cell_type": "code",
   "execution_count": null,
   "id": "e6e67792",
   "metadata": {},
   "outputs": [
    {
     "name": "stdout",
     "output_type": "stream",
     "text": [
      "Please enter a number: куцккк34534\n",
      "Oops!  That was no valid number.  Try again...\n",
      "Please enter a number: 34к34кцыукцу\n",
      "Oops!  That was no valid number.  Try again...\n"
     ]
    }
   ],
   "source": [
    "# _try_except_\n",
    "while True:\n",
    "    try:\n",
    "        x = int(input(\"Please enter a number: \"))\n",
    "        break\n",
    "    except ValueError:\n",
    "        print(\"Oops!  That was no valid number.  Try again...\")"
   ]
  },
  {
   "cell_type": "code",
   "execution_count": null,
   "id": "1cea5627",
   "metadata": {},
   "outputs": [],
   "source": [
    "try:\n",
    "    x = int(input(\"Please enter a number: \"))\n",
    "    break\n",
    "except ValueError:\n",
    "    print(\"Oops!  That was no valid number.  Try again...\")"
   ]
  },
  {
   "cell_type": "markdown",
   "id": "75cfae02",
   "metadata": {},
   "source": [
    "Инструкция try работает следующим образом.\n",
    "\n",
    "Сначала выполняется предложение try (операторы между ключевыми словами try и except).\n",
    "\n",
    "Если исключение не возникает, предложение except пропускается и выполнение инструкции try завершается.\n",
    "\n",
    "\n",
    "Если во время выполнения предложения try возникает исключение, остальная часть предложения пропускается. Затем, если его тип соответствует исключению, названному по ключевому слову except, выполняется предложение except, а затем выполнение продолжается после блока try/except.\n",
    "\n",
    "Если возникает исключение, которое не соответствует исключению, указанному в предложении except, оно передается во внешние операторы try; если обработчик не найден, это необработанное исключение, и выполнение останавливается с сообщением об ошибке.\n",
    "\n",
    "A try statement may have more than one except clause, to specify handlers for different exceptions. At most one handler will be executed. Handlers only handle exceptions that occur in the corresponding try clause, not in other handlers of the same try statement. An except clause may name multiple exceptions as a parenthesized tuple, for example:"
   ]
  },
  {
   "cell_type": "code",
   "execution_count": 4,
   "id": "29391f36",
   "metadata": {},
   "outputs": [
    {
     "ename": "SyntaxError",
     "evalue": "invalid syntax (70789595.py, line 1)",
     "output_type": "error",
     "traceback": [
      "\u001b[1;36m  Cell \u001b[1;32mIn[4], line 1\u001b[1;36m\u001b[0m\n\u001b[1;33m    except (RuntimeError, TypeError, NameError):\u001b[0m\n\u001b[1;37m    ^\u001b[0m\n\u001b[1;31mSyntaxError\u001b[0m\u001b[1;31m:\u001b[0m invalid syntax\n"
     ]
    }
   ],
   "source": [
    "except (RuntimeError, TypeError, NameError):\n",
    "     pass"
   ]
  },
  {
   "cell_type": "markdown",
   "id": "290f134f",
   "metadata": {},
   "source": [
    "A class in an except clause is compatible with an exception if it is the same class or a base class thereof (but not the other way around — an except clause listing a derived class is not compatible with a base class). For example, the following code will print B, C, D in that order:"
   ]
  },
  {
   "cell_type": "code",
   "execution_count": 5,
   "id": "055149b0",
   "metadata": {},
   "outputs": [
    {
     "name": "stdout",
     "output_type": "stream",
     "text": [
      "B\n",
      "C\n",
      "D\n"
     ]
    }
   ],
   "source": [
    "class B(Exception):\n",
    "    pass\n",
    "\n",
    "class C(B):\n",
    "    pass\n",
    "\n",
    "class D(C):\n",
    "    pass\n",
    "\n",
    "for cls in [B, C, D]:\n",
    "    try:\n",
    "        raise cls()\n",
    "    except D:\n",
    "        print(\"D\")\n",
    "    except C:\n",
    "        print(\"C\")\n",
    "    except B:\n",
    "        print(\"B\")"
   ]
  },
  {
   "cell_type": "markdown",
   "id": "4856c074",
   "metadata": {},
   "source": [
    "Note that if the except clauses were reversed (with except B first), it would have printed B, B, B — the first matching except clause is triggered.\n",
    "\n",
    "When an exception occurs, it may have associated values, also known as the exception’s arguments. The presence and types of the arguments depend on the exception type.\n",
    "\n",
    "The except clause may specify a variable after the exception name. The variable is bound to the exception instance which typically has an args attribute that stores the arguments. For convenience, builtin exception types define __str__() to print all the arguments without explicitly accessing .args."
   ]
  },
  {
   "cell_type": "code",
   "execution_count": 6,
   "id": "3de21516",
   "metadata": {},
   "outputs": [
    {
     "ename": "SyntaxError",
     "evalue": "invalid syntax (2967379775.py, line 12)",
     "output_type": "error",
     "traceback": [
      "\u001b[1;36m  Cell \u001b[1;32mIn[6], line 12\u001b[1;36m\u001b[0m\n\u001b[1;33m    <class 'Exception'>\u001b[0m\n\u001b[1;37m    ^\u001b[0m\n\u001b[1;31mSyntaxError\u001b[0m\u001b[1;31m:\u001b[0m invalid syntax\n"
     ]
    }
   ],
   "source": [
    "try:\n",
    "    raise Exception('spam', 'eggs')\n",
    "except Exception as inst:\n",
    "    print(type(inst))    # the exception type\n",
    "    print(inst.args)     # arguments stored in .args\n",
    "    print(inst)          # __str__ allows args to be printed directly,\n",
    "                         # but may be overridden in exception subclasses\n",
    "    x, y = inst.args     # unpack args\n",
    "    print('x =', x)\n",
    "    print('y =', y)\n",
    "\n",
    "<class 'Exception'>\n",
    "('spam', 'eggs')\n",
    "('spam', 'eggs')\n",
    "x = spam\n",
    "y = eggs"
   ]
  },
  {
   "cell_type": "markdown",
   "id": "ff48ddfd",
   "metadata": {},
   "source": [
    "The exception’s __str__() output is printed as the last part (‘detail’) of the message for unhandled exceptions.\n",
    "\n",
    "BaseException is the common base class of all exceptions. One of its subclasses, Exception, is the base class of all the non-fatal exceptions. Exceptions which are not subclasses of Exception are not typically handled, because they are used to indicate that the program should terminate. They include SystemExit which is raised by sys.exit() and KeyboardInterrupt which is raised when a user wishes to interrupt the program.\n",
    "\n",
    "Exception can be used as a wildcard that catches (almost) everything. However, it is good practice to be as specific as possible with the types of exceptions that we intend to handle, and to allow any unexpected exceptions to propagate on.\n",
    "\n",
    "The most common pattern for handling Exception is to print or log the exception and then re-raise it (allowing a caller to handle the exception as well):"
   ]
  },
  {
   "cell_type": "code",
   "execution_count": 7,
   "id": "a868a94c",
   "metadata": {},
   "outputs": [
    {
     "name": "stdout",
     "output_type": "stream",
     "text": [
      "OS error: [Errno 2] No such file or directory: 'myfile.txt'\n"
     ]
    }
   ],
   "source": [
    "import sys\n",
    "\n",
    "try:\n",
    "    f = open('myfile.txt')\n",
    "    s = f.readline()\n",
    "    i = int(s.strip())\n",
    "except OSError as err:\n",
    "    print(\"OS error:\", err)\n",
    "except ValueError:\n",
    "    print(\"Could not convert data to an integer.\")\n",
    "except Exception as err:\n",
    "    print(f\"Unexpected {err=}, {type(err)=}\")\n",
    "    raise"
   ]
  },
  {
   "cell_type": "markdown",
   "id": "2375bc4b",
   "metadata": {},
   "source": [
    "The try … except statement has an optional else clause, which, when present, must follow all except clauses. It is useful for code that must be executed if the try clause does not raise an exception. For example:"
   ]
  },
  {
   "cell_type": "code",
   "execution_count": 8,
   "id": "e13588ff",
   "metadata": {},
   "outputs": [
    {
     "name": "stdout",
     "output_type": "stream",
     "text": [
      "cannot open -f\n",
      "C:\\Users\\SibNout2023\\AppData\\Roaming\\jupyter\\runtime\\kernel-3c2f82c2-de0d-4fd3-934c-95d8e5d6e1d8.json has 12 lines\n"
     ]
    }
   ],
   "source": [
    "for arg in sys.argv[1:]:\n",
    "    try:\n",
    "        f = open(arg, 'r')\n",
    "    except OSError:\n",
    "        print('cannot open', arg)\n",
    "    else:\n",
    "        print(arg, 'has', len(f.readlines()), 'lines')\n",
    "        f.close()"
   ]
  },
  {
   "cell_type": "markdown",
   "id": "71392a28",
   "metadata": {},
   "source": [
    "The use of the else clause is better than adding additional code to the try clause because it avoids accidentally catching an exception that wasn’t raised by the code being protected by the try … except statement.\n",
    "\n",
    "Exception handlers do not handle only exceptions that occur immediately in the try clause, but also those that occur inside functions that are called (even indirectly) in the try clause. For example:"
   ]
  },
  {
   "cell_type": "code",
   "execution_count": 9,
   "id": "c3694af9",
   "metadata": {},
   "outputs": [
    {
     "ename": "SyntaxError",
     "evalue": "invalid syntax (513367487.py, line 9)",
     "output_type": "error",
     "traceback": [
      "\u001b[1;36m  Cell \u001b[1;32mIn[9], line 9\u001b[1;36m\u001b[0m\n\u001b[1;33m    Handling run-time error: division by zero\u001b[0m\n\u001b[1;37m             ^\u001b[0m\n\u001b[1;31mSyntaxError\u001b[0m\u001b[1;31m:\u001b[0m invalid syntax\n"
     ]
    }
   ],
   "source": [
    "def this_fails():\n",
    "    x = 1/0\n",
    "\n",
    "try:\n",
    "    this_fails()\n",
    "except ZeroDivisionError as err:\n",
    "    print('Handling run-time error:', err)\n",
    "\n",
    "Handling run-time error: division by zero"
   ]
  },
  {
   "cell_type": "markdown",
   "id": "09a46ee7",
   "metadata": {},
   "source": [
    "# 8.4. Raising Exceptions\n"
   ]
  },
  {
   "cell_type": "markdown",
   "id": "6a78a113",
   "metadata": {},
   "source": [
    "The raise statement allows the programmer to force a specified exception to occur. For example:\n",
    "\n"
   ]
  },
  {
   "cell_type": "code",
   "execution_count": 10,
   "id": "2d62fdcb",
   "metadata": {},
   "outputs": [
    {
     "ename": "SyntaxError",
     "evalue": "invalid syntax. Perhaps you forgot a comma? (2913283742.py, line 2)",
     "output_type": "error",
     "traceback": [
      "\u001b[1;36m  Cell \u001b[1;32mIn[10], line 2\u001b[1;36m\u001b[0m\n\u001b[1;33m    Traceback (most recent call last):\u001b[0m\n\u001b[1;37m               ^\u001b[0m\n\u001b[1;31mSyntaxError\u001b[0m\u001b[1;31m:\u001b[0m invalid syntax. Perhaps you forgot a comma?\n"
     ]
    }
   ],
   "source": [
    "raise NameError('HiThere')\n",
    "Traceback (most recent call last):\n",
    "  File \"<stdin>\", line 1, in <module>\n",
    "NameError: HiThere"
   ]
  },
  {
   "cell_type": "markdown",
   "id": "ca9f213a",
   "metadata": {},
   "source": [
    "The sole argument to raise indicates the exception to be raised. This must be either an exception instance or an exception class (a class that derives from BaseException, such as Exception or one of its subclasses). If an exception class is passed, it will be implicitly instantiated by calling its constructor with no arguments:\n",
    "\n"
   ]
  },
  {
   "cell_type": "code",
   "execution_count": 11,
   "id": "cbd80767",
   "metadata": {},
   "outputs": [
    {
     "ename": "ValueError",
     "evalue": "",
     "output_type": "error",
     "traceback": [
      "\u001b[1;31m---------------------------------------------------------------------------\u001b[0m",
      "\u001b[1;31mValueError\u001b[0m                                Traceback (most recent call last)",
      "Cell \u001b[1;32mIn[11], line 1\u001b[0m\n\u001b[1;32m----> 1\u001b[0m \u001b[38;5;28;01mraise\u001b[39;00m \u001b[38;5;167;01mValueError\u001b[39;00m\n",
      "\u001b[1;31mValueError\u001b[0m: "
     ]
    }
   ],
   "source": [
    "raise ValueError  # shorthand for 'raise ValueError()'"
   ]
  },
  {
   "cell_type": "markdown",
   "id": "6a345df1",
   "metadata": {},
   "source": [
    "If you need to determine whether an exception was raised but don’t intend to handle it, a simpler form of the raise statement allows you to re-raise the exception:\n",
    "\n"
   ]
  },
  {
   "cell_type": "code",
   "execution_count": 12,
   "id": "33d2213e",
   "metadata": {},
   "outputs": [
    {
     "ename": "SyntaxError",
     "evalue": "invalid syntax (2932141468.py, line 7)",
     "output_type": "error",
     "traceback": [
      "\u001b[1;36m  Cell \u001b[1;32mIn[12], line 7\u001b[1;36m\u001b[0m\n\u001b[1;33m    An exception flew by!\u001b[0m\n\u001b[1;37m       ^\u001b[0m\n\u001b[1;31mSyntaxError\u001b[0m\u001b[1;31m:\u001b[0m invalid syntax\n"
     ]
    }
   ],
   "source": [
    "try:\n",
    "    raise NameError('HiThere')\n",
    "except NameError:\n",
    "    print('An exception flew by!')\n",
    "    raise\n",
    "\n",
    "An exception flew by!\n",
    "Traceback (most recent call last):\n",
    "  File \"<stdin>\", line 2, in <module>\n",
    "NameError: HiThere"
   ]
  },
  {
   "cell_type": "markdown",
   "id": "aff6459a",
   "metadata": {},
   "source": [
    "# 8.5. Exception Chaining\n"
   ]
  },
  {
   "cell_type": "markdown",
   "id": "0288b52f",
   "metadata": {},
   "source": [
    "If an unhandled exception occurs inside an except section, it will have the exception being handled attached to it and included in the error message:\n",
    "\n"
   ]
  },
  {
   "cell_type": "code",
   "execution_count": 13,
   "id": "f018d8a7",
   "metadata": {},
   "outputs": [
    {
     "ename": "SyntaxError",
     "evalue": "invalid syntax. Perhaps you forgot a comma? (2002421475.py, line 6)",
     "output_type": "error",
     "traceback": [
      "\u001b[1;36m  Cell \u001b[1;32mIn[13], line 6\u001b[1;36m\u001b[0m\n\u001b[1;33m    Traceback (most recent call last):\u001b[0m\n\u001b[1;37m               ^\u001b[0m\n\u001b[1;31mSyntaxError\u001b[0m\u001b[1;31m:\u001b[0m invalid syntax. Perhaps you forgot a comma?\n"
     ]
    }
   ],
   "source": [
    "try:\n",
    "    open(\"database.sqlite\")\n",
    "except OSError:\n",
    "    raise RuntimeError(\"unable to handle error\")\n",
    "\n",
    "Traceback (most recent call last):\n",
    "  File \"<stdin>\", line 2, in <module>\n",
    "FileNotFoundError: [Errno 2] No such file or directory: 'database.sqlite'\n",
    "\n",
    "During handling of the above exception, another exception occurred:\n",
    "\n",
    "Traceback (most recent call last):\n",
    "  File \"<stdin>\", line 4, in <module>\n",
    "RuntimeError: unable to handle error"
   ]
  },
  {
   "cell_type": "markdown",
   "id": "12e9a03d",
   "metadata": {},
   "source": [
    "To indicate that an exception is a direct consequence of another, the raise statement allows an optional from clause:\n",
    "\n"
   ]
  },
  {
   "cell_type": "code",
   "execution_count": 14,
   "id": "4c508b9b",
   "metadata": {},
   "outputs": [
    {
     "ename": "NameError",
     "evalue": "name 'exc' is not defined",
     "output_type": "error",
     "traceback": [
      "\u001b[1;31m---------------------------------------------------------------------------\u001b[0m",
      "\u001b[1;31mNameError\u001b[0m                                 Traceback (most recent call last)",
      "Cell \u001b[1;32mIn[14], line 2\u001b[0m\n\u001b[0;32m      1\u001b[0m \u001b[38;5;66;03m# exc must be exception instance or None.\u001b[39;00m\n\u001b[1;32m----> 2\u001b[0m \u001b[38;5;28;01mraise\u001b[39;00m \u001b[38;5;167;01mRuntimeError\u001b[39;00m \u001b[38;5;28;01mfrom\u001b[39;00m \u001b[38;5;21;01mexc\u001b[39;00m\n",
      "\u001b[1;31mNameError\u001b[0m: name 'exc' is not defined"
     ]
    }
   ],
   "source": [
    "# exc must be exception instance or None.\n",
    "raise RuntimeError from exc"
   ]
  },
  {
   "cell_type": "markdown",
   "id": "a3b5e109",
   "metadata": {},
   "source": [
    "This can be useful when you are transforming exceptions. For example:\n",
    "\n"
   ]
  },
  {
   "cell_type": "code",
   "execution_count": 15,
   "id": "077ca8bc",
   "metadata": {},
   "outputs": [
    {
     "ename": "SyntaxError",
     "evalue": "invalid syntax. Perhaps you forgot a comma? (1196750241.py, line 9)",
     "output_type": "error",
     "traceback": [
      "\u001b[1;36m  Cell \u001b[1;32mIn[15], line 9\u001b[1;36m\u001b[0m\n\u001b[1;33m    Traceback (most recent call last):\u001b[0m\n\u001b[1;37m               ^\u001b[0m\n\u001b[1;31mSyntaxError\u001b[0m\u001b[1;31m:\u001b[0m invalid syntax. Perhaps you forgot a comma?\n"
     ]
    }
   ],
   "source": [
    "def func():\n",
    "    raise ConnectionError\n",
    "\n",
    "try:\n",
    "    func()\n",
    "except ConnectionError as exc:\n",
    "    raise RuntimeError('Failed to open database') from exc\n",
    "\n",
    "Traceback (most recent call last):\n",
    "  File \"<stdin>\", line 2, in <module>\n",
    "  File \"<stdin>\", line 2, in func\n",
    "ConnectionError\n",
    "\n",
    "The above exception was the direct cause of the following exception:\n",
    "\n",
    "Traceback (most recent call last):\n",
    "  File \"<stdin>\", line 4, in <module>\n",
    "RuntimeError: Failed to open database"
   ]
  },
  {
   "cell_type": "markdown",
   "id": "d4d6ec67",
   "metadata": {},
   "source": [
    "It also allows disabling automatic exception chaining using the from None idiom:\n",
    "\n"
   ]
  },
  {
   "cell_type": "code",
   "execution_count": 16,
   "id": "78f5346d",
   "metadata": {},
   "outputs": [
    {
     "ename": "SyntaxError",
     "evalue": "invalid syntax. Perhaps you forgot a comma? (2629850775.py, line 6)",
     "output_type": "error",
     "traceback": [
      "\u001b[1;36m  Cell \u001b[1;32mIn[16], line 6\u001b[1;36m\u001b[0m\n\u001b[1;33m    Traceback (most recent call last):\u001b[0m\n\u001b[1;37m               ^\u001b[0m\n\u001b[1;31mSyntaxError\u001b[0m\u001b[1;31m:\u001b[0m invalid syntax. Perhaps you forgot a comma?\n"
     ]
    }
   ],
   "source": [
    "try:\n",
    "    open('database.sqlite')\n",
    "except OSError:\n",
    "    raise RuntimeError from None\n",
    "\n",
    "Traceback (most recent call last):\n",
    "  File \"<stdin>\", line 4, in <module>\n",
    "RuntimeError"
   ]
  },
  {
   "cell_type": "markdown",
   "id": "7bcc7a8e",
   "metadata": {},
   "source": [
    "For more information about chaining mechanics, see Built-in Exceptions.\n",
    "\n"
   ]
  },
  {
   "cell_type": "markdown",
   "id": "43192f81",
   "metadata": {},
   "source": [
    "# 8.6. User-defined Exceptions\n"
   ]
  },
  {
   "cell_type": "markdown",
   "id": "32875dfa",
   "metadata": {},
   "source": [
    "Programs may name their own exceptions by creating a new exception class (see Classes for more about Python classes). Exceptions should typically be derived from the Exception class, either directly or indirectly.\n",
    "\n",
    "Exception classes can be defined which do anything any other class can do, but are usually kept simple, often only offering a number of attributes that allow information about the error to be extracted by handlers for the exception.\n",
    "\n",
    "Most exceptions are defined with names that end in “Error”, similar to the naming of the standard exceptions.\n",
    "\n",
    "Many standard modules define their own exceptions to report errors that may occur in functions they define."
   ]
  },
  {
   "cell_type": "markdown",
   "id": "1ae7c122",
   "metadata": {},
   "source": [
    "# 8.7. Defining Clean-up Actions¶\n"
   ]
  },
  {
   "cell_type": "markdown",
   "id": "2c1d641b",
   "metadata": {},
   "source": [
    "The try statement has another optional clause which is intended to define clean-up actions that must be executed under all circumstances. For example:\n",
    "\n"
   ]
  },
  {
   "cell_type": "code",
   "execution_count": 1,
   "id": "e328e38d",
   "metadata": {},
   "outputs": [
    {
     "ename": "SyntaxError",
     "evalue": "invalid syntax (3845583341.py, line 6)",
     "output_type": "error",
     "traceback": [
      "\u001b[1;36m  Cell \u001b[1;32mIn[1], line 6\u001b[1;36m\u001b[0m\n\u001b[1;33m    Goodbye, world!\u001b[0m\n\u001b[1;37m                  ^\u001b[0m\n\u001b[1;31mSyntaxError\u001b[0m\u001b[1;31m:\u001b[0m invalid syntax\n"
     ]
    }
   ],
   "source": [
    "try:\n",
    "    raise KeyboardInterrupt\n",
    "finally:\n",
    "    print('Goodbye, world!')\n",
    "\n",
    "Goodbye, world!\n",
    "Traceback (most recent call last):\n",
    "  File \"<stdin>\", line 2, in <module>\n",
    "KeyboardInterrupt"
   ]
  },
  {
   "cell_type": "markdown",
   "id": "df2b056d",
   "metadata": {},
   "source": [
    "If a finally clause is present, the finally clause will execute as the last task before the try statement completes. The finally clause runs whether or not the try statement produces an exception. The following points discuss more complex cases when an exception occurs:\n",
    "\n",
    "If an exception occurs during execution of the try clause, the exception may be handled by an except clause. If the exception is not handled by an except clause, the exception is re-raised after the finally clause has been executed.\n",
    "\n",
    "An exception could occur during execution of an except or else clause. Again, the exception is re-raised after the finally clause has been executed.\n",
    "\n",
    "If the finally clause executes a break, continue or return statement, exceptions are not re-raised.\n",
    "\n",
    "If the try statement reaches a break, continue or return statement, the finally clause will execute just prior to the break, continue or return statement’s execution.\n",
    "\n",
    "If a finally clause includes a return statement, the returned value will be the one from the finally clause’s return statement, not the value from the try clause’s return statement.\n",
    "\n",
    "For example:"
   ]
  },
  {
   "cell_type": "code",
   "execution_count": 2,
   "id": "2262b6a5",
   "metadata": {},
   "outputs": [
    {
     "data": {
      "text/plain": [
       "False"
      ]
     },
     "execution_count": 2,
     "metadata": {},
     "output_type": "execute_result"
    }
   ],
   "source": [
    "def bool_return():\n",
    "    try:\n",
    "        return True\n",
    "    finally:\n",
    "        return False\n",
    "\n",
    "bool_return()\n",
    "False"
   ]
  },
  {
   "cell_type": "markdown",
   "id": "bbe9ceb2",
   "metadata": {},
   "source": [
    "A more complicated example:\n",
    "\n"
   ]
  },
  {
   "cell_type": "code",
   "execution_count": 3,
   "id": "52d9a2df",
   "metadata": {},
   "outputs": [
    {
     "ename": "SyntaxError",
     "evalue": "invalid syntax (2339019479.py, line 13)",
     "output_type": "error",
     "traceback": [
      "\u001b[1;36m  Cell \u001b[1;32mIn[3], line 13\u001b[1;36m\u001b[0m\n\u001b[1;33m    executing finally clause\u001b[0m\n\u001b[1;37m              ^\u001b[0m\n\u001b[1;31mSyntaxError\u001b[0m\u001b[1;31m:\u001b[0m invalid syntax\n"
     ]
    }
   ],
   "source": [
    "def divide(x, y):\n",
    "    try:\n",
    "        result = x / y\n",
    "    except ZeroDivisionError:\n",
    "        print(\"division by zero!\")\n",
    "    else:\n",
    "        print(\"result is\", result)\n",
    "    finally:\n",
    "        print(\"executing finally clause\")\n",
    "\n",
    "divide(2, 1)\n",
    "result is 2.0\n",
    "executing finally clause\n",
    "divide(2, 0)\n",
    "division by zero!\n",
    "executing finally clause\n",
    "divide(\"2\", \"1\")\n",
    "executing finally clause\n",
    "Traceback (most recent call last):\n",
    "  File \"<stdin>\", line 1, in <module>\n",
    "  File \"<stdin>\", line 3, in divide\n",
    "TypeError: unsupported operand type(s) for /: 'str' and 'str'"
   ]
  },
  {
   "cell_type": "markdown",
   "id": "c6ecc8af",
   "metadata": {},
   "source": [
    "As you can see, the finally clause is executed in any event. The TypeError raised by dividing two strings is not handled by the except clause and therefore re-raised after the finally clause has been executed.\n",
    "\n",
    "In real world applications, the finally clause is useful for releasing external resources (such as files or network connections), regardless of whether the use of the resource was successful."
   ]
  },
  {
   "cell_type": "markdown",
   "id": "58978e86",
   "metadata": {},
   "source": [
    "# 8.8. Predefined Clean-up Actions\n"
   ]
  },
  {
   "cell_type": "markdown",
   "id": "cd23c761",
   "metadata": {},
   "source": [
    "Some objects define standard clean-up actions to be undertaken when the object is no longer needed, regardless of whether or not the operation using the object succeeded or failed. Look at the following example, which tries to open a file and print its contents to the screen.\n",
    "\n"
   ]
  },
  {
   "cell_type": "code",
   "execution_count": 4,
   "id": "be0dc758",
   "metadata": {},
   "outputs": [
    {
     "ename": "FileNotFoundError",
     "evalue": "[Errno 2] No such file or directory: 'myfile.txt'",
     "output_type": "error",
     "traceback": [
      "\u001b[1;31m---------------------------------------------------------------------------\u001b[0m",
      "\u001b[1;31mFileNotFoundError\u001b[0m                         Traceback (most recent call last)",
      "Cell \u001b[1;32mIn[4], line 1\u001b[0m\n\u001b[1;32m----> 1\u001b[0m \u001b[38;5;28;01mfor\u001b[39;00m line \u001b[38;5;129;01min\u001b[39;00m \u001b[38;5;28mopen\u001b[39m(\u001b[38;5;124m\"\u001b[39m\u001b[38;5;124mmyfile.txt\u001b[39m\u001b[38;5;124m\"\u001b[39m):\n\u001b[0;32m      2\u001b[0m     \u001b[38;5;28mprint\u001b[39m(line, end\u001b[38;5;241m=\u001b[39m\u001b[38;5;124m\"\u001b[39m\u001b[38;5;124m\"\u001b[39m)\n",
      "File \u001b[1;32m~\\anaconda3\\Lib\\site-packages\\IPython\\core\\interactiveshell.py:286\u001b[0m, in \u001b[0;36m_modified_open\u001b[1;34m(file, *args, **kwargs)\u001b[0m\n\u001b[0;32m    279\u001b[0m \u001b[38;5;28;01mif\u001b[39;00m file \u001b[38;5;129;01min\u001b[39;00m {\u001b[38;5;241m0\u001b[39m, \u001b[38;5;241m1\u001b[39m, \u001b[38;5;241m2\u001b[39m}:\n\u001b[0;32m    280\u001b[0m     \u001b[38;5;28;01mraise\u001b[39;00m \u001b[38;5;167;01mValueError\u001b[39;00m(\n\u001b[0;32m    281\u001b[0m         \u001b[38;5;124mf\u001b[39m\u001b[38;5;124m\"\u001b[39m\u001b[38;5;124mIPython won\u001b[39m\u001b[38;5;124m'\u001b[39m\u001b[38;5;124mt let you open fd=\u001b[39m\u001b[38;5;132;01m{\u001b[39;00mfile\u001b[38;5;132;01m}\u001b[39;00m\u001b[38;5;124m by default \u001b[39m\u001b[38;5;124m\"\u001b[39m\n\u001b[0;32m    282\u001b[0m         \u001b[38;5;124m\"\u001b[39m\u001b[38;5;124mas it is likely to crash IPython. If you know what you are doing, \u001b[39m\u001b[38;5;124m\"\u001b[39m\n\u001b[0;32m    283\u001b[0m         \u001b[38;5;124m\"\u001b[39m\u001b[38;5;124myou can use builtins\u001b[39m\u001b[38;5;124m'\u001b[39m\u001b[38;5;124m open.\u001b[39m\u001b[38;5;124m\"\u001b[39m\n\u001b[0;32m    284\u001b[0m     )\n\u001b[1;32m--> 286\u001b[0m \u001b[38;5;28;01mreturn\u001b[39;00m io_open(file, \u001b[38;5;241m*\u001b[39margs, \u001b[38;5;241m*\u001b[39m\u001b[38;5;241m*\u001b[39mkwargs)\n",
      "\u001b[1;31mFileNotFoundError\u001b[0m: [Errno 2] No such file or directory: 'myfile.txt'"
     ]
    }
   ],
   "source": [
    "for line in open(\"myfile.txt\"):\n",
    "    print(line, end=\"\")"
   ]
  },
  {
   "cell_type": "markdown",
   "id": "6a6a4de5",
   "metadata": {},
   "source": [
    "The problem with this code is that it leaves the file open for an indeterminate amount of time after this part of the code has finished executing. This is not an issue in simple scripts, but can be a problem for larger applications. The with statement allows objects like files to be used in a way that ensures they are always cleaned up promptly and correctly."
   ]
  },
  {
   "cell_type": "code",
   "execution_count": 5,
   "id": "689f72ea",
   "metadata": {},
   "outputs": [
    {
     "ename": "FileNotFoundError",
     "evalue": "[Errno 2] No such file or directory: 'myfile.txt'",
     "output_type": "error",
     "traceback": [
      "\u001b[1;31m---------------------------------------------------------------------------\u001b[0m",
      "\u001b[1;31mFileNotFoundError\u001b[0m                         Traceback (most recent call last)",
      "Cell \u001b[1;32mIn[5], line 1\u001b[0m\n\u001b[1;32m----> 1\u001b[0m \u001b[38;5;28;01mwith\u001b[39;00m \u001b[38;5;28mopen\u001b[39m(\u001b[38;5;124m\"\u001b[39m\u001b[38;5;124mmyfile.txt\u001b[39m\u001b[38;5;124m\"\u001b[39m) \u001b[38;5;28;01mas\u001b[39;00m f:\n\u001b[0;32m      2\u001b[0m     \u001b[38;5;28;01mfor\u001b[39;00m line \u001b[38;5;129;01min\u001b[39;00m f:\n\u001b[0;32m      3\u001b[0m         \u001b[38;5;28mprint\u001b[39m(line, end\u001b[38;5;241m=\u001b[39m\u001b[38;5;124m\"\u001b[39m\u001b[38;5;124m\"\u001b[39m)\n",
      "File \u001b[1;32m~\\anaconda3\\Lib\\site-packages\\IPython\\core\\interactiveshell.py:286\u001b[0m, in \u001b[0;36m_modified_open\u001b[1;34m(file, *args, **kwargs)\u001b[0m\n\u001b[0;32m    279\u001b[0m \u001b[38;5;28;01mif\u001b[39;00m file \u001b[38;5;129;01min\u001b[39;00m {\u001b[38;5;241m0\u001b[39m, \u001b[38;5;241m1\u001b[39m, \u001b[38;5;241m2\u001b[39m}:\n\u001b[0;32m    280\u001b[0m     \u001b[38;5;28;01mraise\u001b[39;00m \u001b[38;5;167;01mValueError\u001b[39;00m(\n\u001b[0;32m    281\u001b[0m         \u001b[38;5;124mf\u001b[39m\u001b[38;5;124m\"\u001b[39m\u001b[38;5;124mIPython won\u001b[39m\u001b[38;5;124m'\u001b[39m\u001b[38;5;124mt let you open fd=\u001b[39m\u001b[38;5;132;01m{\u001b[39;00mfile\u001b[38;5;132;01m}\u001b[39;00m\u001b[38;5;124m by default \u001b[39m\u001b[38;5;124m\"\u001b[39m\n\u001b[0;32m    282\u001b[0m         \u001b[38;5;124m\"\u001b[39m\u001b[38;5;124mas it is likely to crash IPython. If you know what you are doing, \u001b[39m\u001b[38;5;124m\"\u001b[39m\n\u001b[0;32m    283\u001b[0m         \u001b[38;5;124m\"\u001b[39m\u001b[38;5;124myou can use builtins\u001b[39m\u001b[38;5;124m'\u001b[39m\u001b[38;5;124m open.\u001b[39m\u001b[38;5;124m\"\u001b[39m\n\u001b[0;32m    284\u001b[0m     )\n\u001b[1;32m--> 286\u001b[0m \u001b[38;5;28;01mreturn\u001b[39;00m io_open(file, \u001b[38;5;241m*\u001b[39margs, \u001b[38;5;241m*\u001b[39m\u001b[38;5;241m*\u001b[39mkwargs)\n",
      "\u001b[1;31mFileNotFoundError\u001b[0m: [Errno 2] No such file or directory: 'myfile.txt'"
     ]
    }
   ],
   "source": [
    "with open(\"myfile.txt\") as f:\n",
    "    for line in f:\n",
    "        print(line, end=\"\")"
   ]
  },
  {
   "cell_type": "markdown",
   "id": "8998e5a2",
   "metadata": {},
   "source": [
    "After the statement is executed, the file f is always closed, even if a problem was encountered while processing the lines. Objects which, like files, provide predefined clean-up actions will indicate this in their documentation.\n",
    "\n"
   ]
  },
  {
   "cell_type": "markdown",
   "id": "10ac7f34",
   "metadata": {},
   "source": [
    "# 8.9. Raising and Handling Multiple Unrelated Exceptions\n"
   ]
  },
  {
   "cell_type": "markdown",
   "id": "8cbc8b7d",
   "metadata": {},
   "source": [
    "There are situations where it is necessary to report several exceptions that have occurred. This is often the case in concurrency frameworks, when several tasks may have failed in parallel, but there are also other use cases where it is desirable to continue execution and collect multiple errors rather than raise the first exception.\n",
    "\n",
    "The builtin ExceptionGroup wraps a list of exception instances so that they can be raised together. It is an exception itself, so it can be caught like any other exception."
   ]
  },
  {
   "cell_type": "code",
   "execution_count": 7,
   "id": "b8365a1f",
   "metadata": {},
   "outputs": [
    {
     "ename": "IndentationError",
     "evalue": "unexpected indent (2237246291.py, line 6)",
     "output_type": "error",
     "traceback": [
      "\u001b[1;36m  Cell \u001b[1;32mIn[7], line 6\u001b[1;36m\u001b[0m\n\u001b[1;33m    + Exception Group Traceback (most recent call last):\u001b[0m\n\u001b[1;37m    ^\u001b[0m\n\u001b[1;31mIndentationError\u001b[0m\u001b[1;31m:\u001b[0m unexpected indent\n"
     ]
    }
   ],
   "source": [
    "def f():\n",
    "    excs = [OSError('error 1'), SystemError('error 2')]\n",
    "    raise ExceptionGroup('there were problems', excs)\n",
    "\n",
    "f()\n",
    "  + Exception Group Traceback (most recent call last):\n",
    "  |   File \"<stdin>\", line 1, in <module>\n",
    "  |   File \"<stdin>\", line 3, in f\n",
    "  | ExceptionGroup: there were problems\n",
    "  +-+---------------- 1 ----------------\n",
    "    | OSError: error 1\n",
    "    +---------------- 2 ----------------\n",
    "    | SystemError: error 2\n",
    "    +------------------------------------\n",
    "try:\n",
    "    f()\n",
    "except Exception as e:\n",
    "    print(f'caught {type(e)}: e')\n",
    "\n",
    "caught <class 'ExceptionGroup'>: e\n"
   ]
  },
  {
   "cell_type": "markdown",
   "id": "42b48070",
   "metadata": {},
   "source": [
    "By using except* instead of except, we can selectively handle only the exceptions in the group that match a certain type. In the following example, which shows a nested exception group, each except* clause extracts from the group exceptions of a certain type while letting all other exceptions propagate to other clauses and eventually to be reraised."
   ]
  },
  {
   "cell_type": "code",
   "execution_count": 8,
   "id": "6dea9bab",
   "metadata": {},
   "outputs": [
    {
     "ename": "SyntaxError",
     "evalue": "invalid syntax (3164185287.py, line 24)",
     "output_type": "error",
     "traceback": [
      "\u001b[1;36m  Cell \u001b[1;32mIn[8], line 24\u001b[1;36m\u001b[0m\n\u001b[1;33m    There were OSErrors\u001b[0m\n\u001b[1;37m          ^\u001b[0m\n\u001b[1;31mSyntaxError\u001b[0m\u001b[1;31m:\u001b[0m invalid syntax\n"
     ]
    }
   ],
   "source": [
    "def f():\n",
    "    raise ExceptionGroup(\n",
    "        \"group1\",\n",
    "        [\n",
    "            OSError(1),\n",
    "            SystemError(2),\n",
    "            ExceptionGroup(\n",
    "                \"group2\",\n",
    "                [\n",
    "                    OSError(3),\n",
    "                    RecursionError(4)\n",
    "                ]\n",
    "            )\n",
    "        ]\n",
    "    )\n",
    "\n",
    "try:\n",
    "    f()\n",
    "except* OSError as e:\n",
    "    print(\"There were OSErrors\")\n",
    "except* SystemError as e:\n",
    "    print(\"There were SystemErrors\")\n",
    "\n",
    "There were OSErrors\n",
    "There were SystemErrors\n",
    "  + Exception Group Traceback (most recent call last):\n",
    "  |   File \"<stdin>\", line 2, in <module>\n",
    "  |   File \"<stdin>\", line 2, in f\n",
    "  | ExceptionGroup: group1\n",
    "  +-+---------------- 1 ----------------\n",
    "    | ExceptionGroup: group2\n",
    "    +-+---------------- 1 ----------------\n",
    "      | RecursionError: 4\n",
    "      +------------------------------------\n"
   ]
  },
  {
   "cell_type": "markdown",
   "id": "8777788e",
   "metadata": {},
   "source": [
    "Note that the exceptions nested in an exception group must be instances, not types. This is because in practice the exceptions would typically be ones that have already been raised and caught by the program, along the following pattern:"
   ]
  },
  {
   "cell_type": "code",
   "execution_count": 9,
   "id": "340a5e48",
   "metadata": {},
   "outputs": [
    {
     "ename": "NameError",
     "evalue": "name 'tests' is not defined",
     "output_type": "error",
     "traceback": [
      "\u001b[1;31m---------------------------------------------------------------------------\u001b[0m",
      "\u001b[1;31mNameError\u001b[0m                                 Traceback (most recent call last)",
      "Cell \u001b[1;32mIn[9], line 2\u001b[0m\n\u001b[0;32m      1\u001b[0m excs \u001b[38;5;241m=\u001b[39m []\n\u001b[1;32m----> 2\u001b[0m \u001b[38;5;28;01mfor\u001b[39;00m test \u001b[38;5;129;01min\u001b[39;00m tests:\n\u001b[0;32m      3\u001b[0m     \u001b[38;5;28;01mtry\u001b[39;00m:\n\u001b[0;32m      4\u001b[0m         test\u001b[38;5;241m.\u001b[39mrun()\n",
      "\u001b[1;31mNameError\u001b[0m: name 'tests' is not defined"
     ]
    }
   ],
   "source": [
    "excs = []\n",
    "for test in tests:\n",
    "    try:\n",
    "        test.run()\n",
    "    except Exception as e:\n",
    "        excs.append(e)\n",
    "\n",
    "if excs:\n",
    "   raise ExceptionGroup(\"Test Failures\", excs)\n"
   ]
  },
  {
   "cell_type": "markdown",
   "id": "0a140701",
   "metadata": {},
   "source": [
    "# 8.10. Enriching Exceptions with Notes¶\n"
   ]
  },
  {
   "cell_type": "markdown",
   "id": "4a95690c",
   "metadata": {},
   "source": [
    "When an exception is created in order to be raised, it is usually initialized with information that describes the error that has occurred. There are cases where it is useful to add information after the exception was caught. For this purpose, exceptions have a method add_note(note) that accepts a string and adds it to the exception’s notes list. The standard traceback rendering includes all notes, in the order they were added, after the exception.\n",
    "\n"
   ]
  },
  {
   "cell_type": "code",
   "execution_count": 10,
   "id": "e86a0431",
   "metadata": {},
   "outputs": [
    {
     "ename": "SyntaxError",
     "evalue": "invalid syntax. Perhaps you forgot a comma? (680459096.py, line 8)",
     "output_type": "error",
     "traceback": [
      "\u001b[1;36m  Cell \u001b[1;32mIn[10], line 8\u001b[1;36m\u001b[0m\n\u001b[1;33m    Traceback (most recent call last):\u001b[0m\n\u001b[1;37m               ^\u001b[0m\n\u001b[1;31mSyntaxError\u001b[0m\u001b[1;31m:\u001b[0m invalid syntax. Perhaps you forgot a comma?\n"
     ]
    }
   ],
   "source": [
    "try:\n",
    "    raise TypeError('bad type')\n",
    "except Exception as e:\n",
    "    e.add_note('Add some information')\n",
    "    e.add_note('Add some more information')\n",
    "    raise\n",
    "\n",
    "Traceback (most recent call last):\n",
    "  File \"<stdin>\", line 2, in <module>\n",
    "TypeError: bad type\n",
    "Add some information\n",
    "Add some more information\n"
   ]
  },
  {
   "cell_type": "markdown",
   "id": "8030b1fe",
   "metadata": {},
   "source": [
    "For example, when collecting exceptions into an exception group, we may want to add context information for the individual errors. In the following each exception in the group has a note indicating when this error has occurred.\n",
    "\n"
   ]
  },
  {
   "cell_type": "code",
   "execution_count": 11,
   "id": "bc49eed5",
   "metadata": {},
   "outputs": [
    {
     "ename": "IndentationError",
     "evalue": "unexpected indent (814544796.py, line 13)",
     "output_type": "error",
     "traceback": [
      "\u001b[1;36m  Cell \u001b[1;32mIn[11], line 13\u001b[1;36m\u001b[0m\n\u001b[1;33m    + Exception Group Traceback (most recent call last):\u001b[0m\n\u001b[1;37m    ^\u001b[0m\n\u001b[1;31mIndentationError\u001b[0m\u001b[1;31m:\u001b[0m unexpected indent\n"
     ]
    }
   ],
   "source": [
    "def f():\n",
    "    raise OSError('operation failed')\n",
    "\n",
    "excs = []\n",
    "for i in range(3):\n",
    "    try:\n",
    "        f()\n",
    "    except Exception as e:\n",
    "        e.add_note(f'Happened in Iteration {i+1}')\n",
    "        excs.append(e)\n",
    "\n",
    "raise ExceptionGroup('We have some problems', excs)\n",
    "  + Exception Group Traceback (most recent call last):\n",
    "  |   File \"<stdin>\", line 1, in <module>\n",
    "  | ExceptionGroup: We have some problems (3 sub-exceptions)\n",
    "  +-+---------------- 1 ----------------\n",
    "    | Traceback (most recent call last):\n",
    "    |   File \"<stdin>\", line 3, in <module>\n",
    "    |   File \"<stdin>\", line 2, in f\n",
    "    | OSError: operation failed\n",
    "    | Happened in Iteration 1\n",
    "    +---------------- 2 ----------------\n",
    "    | Traceback (most recent call last):\n",
    "    |   File \"<stdin>\", line 3, in <module>\n",
    "    |   File \"<stdin>\", line 2, in f\n",
    "    | OSError: operation failed\n",
    "    | Happened in Iteration 2\n",
    "    +---------------- 3 ----------------\n",
    "    | Traceback (most recent call last):\n",
    "    |   File \"<stdin>\", line 3, in <module>\n",
    "    |   File \"<stdin>\", line 2, in f\n",
    "    | OSError: operation failed\n",
    "    | Happened in Iteration 3\n",
    "    +------------------------------------\n"
   ]
  },
  {
   "cell_type": "code",
   "execution_count": null,
   "id": "ef1eec3a",
   "metadata": {},
   "outputs": [],
   "source": []
  }
 ],
 "metadata": {
  "kernelspec": {
   "display_name": "Python 3 (ipykernel)",
   "language": "python",
   "name": "python3"
  },
  "language_info": {
   "codemirror_mode": {
    "name": "ipython",
    "version": 3
   },
   "file_extension": ".py",
   "mimetype": "text/x-python",
   "name": "python",
   "nbconvert_exporter": "python",
   "pygments_lexer": "ipython3",
   "version": "3.11.4"
  }
 },
 "nbformat": 4,
 "nbformat_minor": 5
}
